[2025-03-17T20:40:27.851+0000] {local_task_job_runner.py:123} INFO - ::group::Pre task execution logs
[2025-03-17T20:40:29.161+0000] {taskinstance.py:2613} INFO - Dependencies all met for dep_context=non-requeueable deps ti=<TaskInstance: etl_dag.load_tables.events_project_a_db scheduled__2025-03-17T20:30:00+00:00 [queued]>
[2025-03-17T20:40:30.050+0000] {taskinstance.py:2613} INFO - Dependencies all met for dep_context=requeueable deps ti=<TaskInstance: etl_dag.load_tables.events_project_a_db scheduled__2025-03-17T20:30:00+00:00 [queued]>
[2025-03-17T20:40:30.200+0000] {taskinstance.py:2866} INFO - Starting attempt 1 of 2
[2025-03-17T20:40:33.281+0000] {taskinstance.py:2889} INFO - Executing <Task(PostgresOperator): load_tables.events_project_a_db> on 2025-03-17 20:30:00+00:00
[2025-03-17T20:40:33.710+0000] {warnings.py:112} WARNING - /home/***/.local/lib/python3.12/site-packages/***/task/task_runner/standard_task_runner.py:70: DeprecationWarning: This process (pid=3809) is multi-threaded, use of fork() may lead to deadlocks in the child.
  pid = os.fork()

[2025-03-17T20:40:33.800+0000] {standard_task_runner.py:72} INFO - Started process 3826 to run task
[2025-03-17T20:40:33.811+0000] {standard_task_runner.py:104} INFO - Running: ['***', 'tasks', 'run', 'etl_dag', 'load_tables.events_project_a_db', 'scheduled__2025-03-17T20:30:00+00:00', '--job-id', '269', '--raw', '--subdir', 'DAGS_FOLDER/etl.py', '--cfg-path', '/tmp/tmp7vc3py0p']
[2025-03-17T20:40:33.851+0000] {standard_task_runner.py:105} INFO - Job 269: Subtask load_tables.events_project_a_db
[2025-03-17T20:40:38.521+0000] {task_command.py:467} INFO - Running <TaskInstance: etl_dag.load_tables.events_project_a_db scheduled__2025-03-17T20:30:00+00:00 [running]> on host c032966e105e
[2025-03-17T20:40:39.831+0000] {job.py:229} INFO - Heartbeat recovered after 15.18 seconds
[2025-03-17T20:40:44.941+0000] {taskinstance.py:3132} INFO - Exporting env vars: AIRFLOW_CTX_DAG_OWNER='***' AIRFLOW_CTX_DAG_ID='etl_dag' AIRFLOW_CTX_TASK_ID='load_tables.events_project_a_db' AIRFLOW_CTX_EXECUTION_DATE='2025-03-17T20:30:00+00:00' AIRFLOW_CTX_TRY_NUMBER='1' AIRFLOW_CTX_DAG_RUN_ID='scheduled__2025-03-17T20:30:00+00:00'
[2025-03-17T20:40:44.961+0000] {taskinstance.py:731} INFO - ::endgroup::
[2025-03-17T20:40:49.139+0000] {sql.py:278} INFO - Executing: select load_tables('events_project_a_db', 'events');
[2025-03-17T20:40:53.299+0000] {base.py:84} INFO - Retrieving connection 'con_agg'
[2025-03-17T20:40:57.769+0000] {base.py:84} INFO - Retrieving connection 'con_agg'
[2025-03-17T20:40:58.709+0000] {taskinstance.py:3311} ERROR - Task failed with exception
Traceback (most recent call last):
  File "/home/airflow/.local/lib/python3.12/site-packages/airflow/models/taskinstance.py", line 767, in _execute_task
    result = _execute_callable(context=context, **execute_callable_kwargs)
             ^^^^^^^^^^^^^^^^^^^^^^^^^^^^^^^^^^^^^^^^^^^^^^^^^^^^^^^^^^^^^
  File "/home/airflow/.local/lib/python3.12/site-packages/airflow/models/taskinstance.py", line 733, in _execute_callable
    return ExecutionCallableRunner(
           ^^^^^^^^^^^^^^^^^^^^^^^^
  File "/home/airflow/.local/lib/python3.12/site-packages/airflow/utils/operator_helpers.py", line 252, in run
    return self.func(*args, **kwargs)
           ^^^^^^^^^^^^^^^^^^^^^^^^^^
  File "/home/airflow/.local/lib/python3.12/site-packages/airflow/models/baseoperator.py", line 422, in wrapper
    return func(self, *args, **kwargs)
           ^^^^^^^^^^^^^^^^^^^^^^^^^^^
  File "/home/airflow/.local/lib/python3.12/site-packages/airflow/providers/common/sql/operators/sql.py", line 284, in execute
    output = hook.run(
             ^^^^^^^^^
  File "/home/airflow/.local/lib/python3.12/site-packages/airflow/providers/common/sql/hooks/sql.py", line 494, in run
    with self._create_autocommit_connection(autocommit) as conn:
         ^^^^^^^^^^^^^^^^^^^^^^^^^^^^^^^^^^^^^^^^^^^^^^
  File "/usr/local/lib/python3.12/contextlib.py", line 137, in __enter__
    return next(self.gen)
           ^^^^^^^^^^^^^^
  File "/home/airflow/.local/lib/python3.12/site-packages/airflow/providers/common/sql/hooks/sql.py", line 618, in _create_autocommit_connection
    with closing(self.get_conn()) as conn:
                 ^^^^^^^^^^^^^^^
  File "/home/airflow/.local/lib/python3.12/site-packages/airflow/providers/postgres/hooks/postgres.py", line 189, in get_conn
    self.conn = psycopg2.connect(**conn_args)
                ^^^^^^^^^^^^^^^^^^^^^^^^^^^^^
  File "/home/airflow/.local/lib/python3.12/site-packages/psycopg2/__init__.py", line 122, in connect
    conn = _connect(dsn, connection_factory=connection_factory, **kwasync)
           ^^^^^^^^^^^^^^^^^^^^^^^^^^^^^^^^^^^^^^^^^^^^^^^^^^^^^^^^^^^^^^^
psycopg2.OperationalError: connection to server at "pg_dp_agg" (172.22.0.3), port 5432 failed: Connection refused
	Is the server running on that host and accepting TCP/IP connections?

